2020-03-10 13:00:34,088 ERROR: Exception on /user/20 [GET] [in c:\users\domwh\pycharmprojects\recommender-systems-coursework\venv\lib\site-packages\flask\app.py:1891]
Traceback (most recent call last):
  File "c:\users\domwh\pycharmprojects\recommender-systems-coursework\venv\lib\site-packages\flask\app.py", line 2446, in wsgi_app
    response = self.full_dispatch_request()
  File "c:\users\domwh\pycharmprojects\recommender-systems-coursework\venv\lib\site-packages\flask\app.py", line 1951, in full_dispatch_request
    rv = self.handle_user_exception(e)
  File "c:\users\domwh\pycharmprojects\recommender-systems-coursework\venv\lib\site-packages\flask\app.py", line 1820, in handle_user_exception
    reraise(exc_type, exc_value, tb)
  File "c:\users\domwh\pycharmprojects\recommender-systems-coursework\venv\lib\site-packages\flask\_compat.py", line 39, in reraise
    raise value
  File "c:\users\domwh\pycharmprojects\recommender-systems-coursework\venv\lib\site-packages\flask\app.py", line 1949, in full_dispatch_request
    rv = self.dispatch_request()
  File "c:\users\domwh\pycharmprojects\recommender-systems-coursework\venv\lib\site-packages\flask\app.py", line 1935, in dispatch_request
    return self.view_functions[rule.endpoint](**req.view_args)
  File "C:\Users\domwh\PycharmProjects\Recommender-Systems-Coursework\app\main\routes.py", line 46, in user
    recommendations = user.get_recommendations()
  File "C:\Users\domwh\PycharmProjects\Recommender-Systems-Coursework\app\models.py", line 71, in get_recommendations
    track = Track.query.get(int(row["track_id"]))
TypeError: tuple indices must be integers or slices, not str
2020-03-10 13:01:01,152 INFO: ffgt86 startup [in C:\Users\domwh\PycharmProjects\Recommender-Systems-Coursework\app\__init__.py:56]
2020-03-10 13:01:26,932 ERROR: Exception on /user/20 [GET] [in c:\users\domwh\pycharmprojects\recommender-systems-coursework\venv\lib\site-packages\flask\app.py:1891]
Traceback (most recent call last):
  File "c:\users\domwh\pycharmprojects\recommender-systems-coursework\venv\lib\site-packages\flask\app.py", line 2446, in wsgi_app
    response = self.full_dispatch_request()
  File "c:\users\domwh\pycharmprojects\recommender-systems-coursework\venv\lib\site-packages\flask\app.py", line 1951, in full_dispatch_request
    rv = self.handle_user_exception(e)
  File "c:\users\domwh\pycharmprojects\recommender-systems-coursework\venv\lib\site-packages\flask\app.py", line 1820, in handle_user_exception
    reraise(exc_type, exc_value, tb)
  File "c:\users\domwh\pycharmprojects\recommender-systems-coursework\venv\lib\site-packages\flask\_compat.py", line 39, in reraise
    raise value
  File "c:\users\domwh\pycharmprojects\recommender-systems-coursework\venv\lib\site-packages\flask\app.py", line 1949, in full_dispatch_request
    rv = self.dispatch_request()
  File "c:\users\domwh\pycharmprojects\recommender-systems-coursework\venv\lib\site-packages\flask\app.py", line 1935, in dispatch_request
    return self.view_functions[rule.endpoint](**req.view_args)
  File "C:\Users\domwh\PycharmProjects\Recommender-Systems-Coursework\app\main\routes.py", line 46, in user
    recommendations = user.get_recommendations()
  File "C:\Users\domwh\PycharmProjects\Recommender-Systems-Coursework\app\models.py", line 71, in get_recommendations
    print(row["track_id"])
TypeError: tuple indices must be integers or slices, not str
2020-03-10 13:01:51,328 INFO: ffgt86 startup [in C:\Users\domwh\PycharmProjects\Recommender-Systems-Coursework\app\__init__.py:56]
2020-03-10 13:01:52,944 ERROR: Exception on /user/20 [GET] [in c:\users\domwh\pycharmprojects\recommender-systems-coursework\venv\lib\site-packages\flask\app.py:1891]
Traceback (most recent call last):
  File "c:\users\domwh\pycharmprojects\recommender-systems-coursework\venv\lib\site-packages\flask\app.py", line 2446, in wsgi_app
    response = self.full_dispatch_request()
  File "c:\users\domwh\pycharmprojects\recommender-systems-coursework\venv\lib\site-packages\flask\app.py", line 1951, in full_dispatch_request
    rv = self.handle_user_exception(e)
  File "c:\users\domwh\pycharmprojects\recommender-systems-coursework\venv\lib\site-packages\flask\app.py", line 1820, in handle_user_exception
    reraise(exc_type, exc_value, tb)
  File "c:\users\domwh\pycharmprojects\recommender-systems-coursework\venv\lib\site-packages\flask\_compat.py", line 39, in reraise
    raise value
  File "c:\users\domwh\pycharmprojects\recommender-systems-coursework\venv\lib\site-packages\flask\app.py", line 1949, in full_dispatch_request
    rv = self.dispatch_request()
  File "c:\users\domwh\pycharmprojects\recommender-systems-coursework\venv\lib\site-packages\flask\app.py", line 1935, in dispatch_request
    return self.view_functions[rule.endpoint](**req.view_args)
  File "C:\Users\domwh\PycharmProjects\Recommender-Systems-Coursework\app\main\routes.py", line 46, in user
    recommendations = user.get_recommendations()
  File "C:\Users\domwh\PycharmProjects\Recommender-Systems-Coursework\app\models.py", line 71, in get_recommendations
    print(row["track_id"])
TypeError: tuple indices must be integers or slices, not str
2020-03-10 13:02:23,400 INFO: ffgt86 startup [in C:\Users\domwh\PycharmProjects\Recommender-Systems-Coursework\app\__init__.py:56]
2020-03-10 13:02:31,445 ERROR: Exception on /user/20 [GET] [in c:\users\domwh\pycharmprojects\recommender-systems-coursework\venv\lib\site-packages\flask\app.py:1891]
Traceback (most recent call last):
  File "c:\users\domwh\pycharmprojects\recommender-systems-coursework\venv\lib\site-packages\flask\app.py", line 2446, in wsgi_app
    response = self.full_dispatch_request()
  File "c:\users\domwh\pycharmprojects\recommender-systems-coursework\venv\lib\site-packages\flask\app.py", line 1951, in full_dispatch_request
    rv = self.handle_user_exception(e)
  File "c:\users\domwh\pycharmprojects\recommender-systems-coursework\venv\lib\site-packages\flask\app.py", line 1820, in handle_user_exception
    reraise(exc_type, exc_value, tb)
  File "c:\users\domwh\pycharmprojects\recommender-systems-coursework\venv\lib\site-packages\flask\_compat.py", line 39, in reraise
    raise value
  File "c:\users\domwh\pycharmprojects\recommender-systems-coursework\venv\lib\site-packages\flask\app.py", line 1949, in full_dispatch_request
    rv = self.dispatch_request()
  File "c:\users\domwh\pycharmprojects\recommender-systems-coursework\venv\lib\site-packages\flask\app.py", line 1935, in dispatch_request
    return self.view_functions[rule.endpoint](**req.view_args)
  File "C:\Users\domwh\PycharmProjects\Recommender-Systems-Coursework\app\main\routes.py", line 46, in user
    recommendations = user.get_recommendations()
  File "C:\Users\domwh\PycharmProjects\Recommender-Systems-Coursework\app\models.py", line 74, in get_recommendations
    print(row["track_id"])
TypeError: tuple indices must be integers or slices, not str
2020-03-10 13:03:20,571 INFO: ffgt86 startup [in C:\Users\domwh\PycharmProjects\Recommender-Systems-Coursework\app\__init__.py:56]
2020-03-10 13:04:43,230 INFO: ffgt86 startup [in C:\Users\domwh\PycharmProjects\Recommender-Systems-Coursework\app\__init__.py:56]
2020-03-10 13:05:07,539 INFO: ffgt86 startup [in C:\Users\domwh\PycharmProjects\Recommender-Systems-Coursework\app\__init__.py:56]
2020-03-10 13:10:16,914 INFO: ffgt86 startup [in C:\Users\domwh\PycharmProjects\Recommender-Systems-Coursework\app\__init__.py:56]
2020-03-10 13:12:10,689 INFO: ffgt86 startup [in C:\Users\domwh\PycharmProjects\Recommender-Systems-Coursework\app\__init__.py:56]
2020-03-10 13:17:15,868 INFO: ffgt86 startup [in C:\Users\domwh\PycharmProjects\Recommender-Systems-Coursework\app\__init__.py:56]
2020-03-10 13:18:51,167 INFO: ffgt86 startup [in C:\Users\domwh\PycharmProjects\Recommender-Systems-Coursework\app\__init__.py:56]
2020-03-10 13:20:32,681 INFO: ffgt86 startup [in C:\Users\domwh\PycharmProjects\Recommender-Systems-Coursework\app\__init__.py:56]
2020-03-10 13:26:06,299 INFO: ffgt86 startup [in C:\Users\domwh\PycharmProjects\Recommender-Systems-Coursework\app\__init__.py:56]
2020-03-10 13:28:57,462 ERROR: Exception on /user/20 [POST] [in c:\users\domwh\pycharmprojects\recommender-systems-coursework\venv\lib\site-packages\flask\app.py:1891]
Traceback (most recent call last):
  File "c:\users\domwh\pycharmprojects\recommender-systems-coursework\venv\lib\site-packages\flask\app.py", line 2446, in wsgi_app
    response = self.full_dispatch_request()
  File "c:\users\domwh\pycharmprojects\recommender-systems-coursework\venv\lib\site-packages\flask\app.py", line 1951, in full_dispatch_request
    rv = self.handle_user_exception(e)
  File "c:\users\domwh\pycharmprojects\recommender-systems-coursework\venv\lib\site-packages\flask\app.py", line 1820, in handle_user_exception
    reraise(exc_type, exc_value, tb)
  File "c:\users\domwh\pycharmprojects\recommender-systems-coursework\venv\lib\site-packages\flask\_compat.py", line 39, in reraise
    raise value
  File "c:\users\domwh\pycharmprojects\recommender-systems-coursework\venv\lib\site-packages\flask\app.py", line 1949, in full_dispatch_request
    rv = self.dispatch_request()
  File "c:\users\domwh\pycharmprojects\recommender-systems-coursework\venv\lib\site-packages\flask\app.py", line 1935, in dispatch_request
    return self.view_functions[rule.endpoint](**req.view_args)
  File "C:\Users\domwh\PycharmProjects\Recommender-Systems-Coursework\app\main\routes.py", line 32, in user
    recommendations = user.get_recommendations(context_form.to_context())
  File "C:\Users\domwh\PycharmProjects\Recommender-Systems-Coursework\app\models.py", line 61, in get_recommendations
    weight += B[i, context[key]]
IndexError: index 42 is out of bounds for axis 1 with size 24
2020-03-10 13:34:27,572 INFO: ffgt86 startup [in C:\Users\domwh\PycharmProjects\Recommender-Systems-Coursework\app\__init__.py:56]
