2020-03-10 12:50:08,405 ERROR: Exception on /user/20 [GET] [in c:\users\domwh\pycharmprojects\recommender-systems-coursework\venv\lib\site-packages\flask\app.py:1891]
Traceback (most recent call last):
  File "c:\users\domwh\pycharmprojects\recommender-systems-coursework\venv\lib\site-packages\flask\app.py", line 2446, in wsgi_app
    response = self.full_dispatch_request()
  File "c:\users\domwh\pycharmprojects\recommender-systems-coursework\venv\lib\site-packages\flask\app.py", line 1951, in full_dispatch_request
    rv = self.handle_user_exception(e)
  File "c:\users\domwh\pycharmprojects\recommender-systems-coursework\venv\lib\site-packages\flask\app.py", line 1820, in handle_user_exception
    reraise(exc_type, exc_value, tb)
  File "c:\users\domwh\pycharmprojects\recommender-systems-coursework\venv\lib\site-packages\flask\_compat.py", line 39, in reraise
    raise value
  File "c:\users\domwh\pycharmprojects\recommender-systems-coursework\venv\lib\site-packages\flask\app.py", line 1949, in full_dispatch_request
    rv = self.dispatch_request()
  File "c:\users\domwh\pycharmprojects\recommender-systems-coursework\venv\lib\site-packages\flask\app.py", line 1935, in dispatch_request
    return self.view_functions[rule.endpoint](**req.view_args)
  File "C:\Users\domwh\PycharmProjects\Recommender-Systems-Coursework\app\main\routes.py", line 46, in user
    recommendations = user.get_recommendations()
  File "C:\Users\domwh\PycharmProjects\Recommender-Systems-Coursework\app\models.py", line 73, in get_recommendations
    x = Track.query.add_columns(Artist.name).get(track_id)
  File "c:\users\domwh\pycharmprojects\recommender-systems-coursework\venv\lib\site-packages\sqlalchemy\orm\query.py", line 982, in get
    return self._get_impl(ident, loading.load_on_pk_identity)
  File "c:\users\domwh\pycharmprojects\recommender-systems-coursework\venv\lib\site-packages\sqlalchemy\orm\query.py", line 1043, in _get_impl
    mapper = self._only_full_mapper_zero("get")
  File "c:\users\domwh\pycharmprojects\recommender-systems-coursework\venv\lib\site-packages\sqlalchemy\orm\query.py", line 409, in _only_full_mapper_zero
    "a single mapped class." % methname
sqlalchemy.exc.InvalidRequestError: get() can only be used against a single mapped class.
2020-03-10 12:50:31,634 INFO: ffgt86 startup [in C:\Users\domwh\PycharmProjects\Recommender-Systems-Coursework\app\__init__.py:56]
2020-03-10 12:52:30,140 INFO: ffgt86 startup [in C:\Users\domwh\PycharmProjects\Recommender-Systems-Coursework\app\__init__.py:56]
2020-03-10 12:54:14,770 INFO: ffgt86 startup [in C:\Users\domwh\PycharmProjects\Recommender-Systems-Coursework\app\__init__.py:56]
2020-03-10 12:57:08,382 INFO: ffgt86 startup [in C:\Users\domwh\PycharmProjects\Recommender-Systems-Coursework\app\__init__.py:56]
2020-03-10 12:57:32,706 ERROR: Exception on /user/20 [GET] [in c:\users\domwh\pycharmprojects\recommender-systems-coursework\venv\lib\site-packages\flask\app.py:1891]
Traceback (most recent call last):
  File "c:\users\domwh\pycharmprojects\recommender-systems-coursework\venv\lib\site-packages\flask\app.py", line 2446, in wsgi_app
    response = self.full_dispatch_request()
  File "c:\users\domwh\pycharmprojects\recommender-systems-coursework\venv\lib\site-packages\flask\app.py", line 1951, in full_dispatch_request
    rv = self.handle_user_exception(e)
  File "c:\users\domwh\pycharmprojects\recommender-systems-coursework\venv\lib\site-packages\flask\app.py", line 1820, in handle_user_exception
    reraise(exc_type, exc_value, tb)
  File "c:\users\domwh\pycharmprojects\recommender-systems-coursework\venv\lib\site-packages\flask\_compat.py", line 39, in reraise
    raise value
  File "c:\users\domwh\pycharmprojects\recommender-systems-coursework\venv\lib\site-packages\flask\app.py", line 1949, in full_dispatch_request
    rv = self.dispatch_request()
  File "c:\users\domwh\pycharmprojects\recommender-systems-coursework\venv\lib\site-packages\flask\app.py", line 1935, in dispatch_request
    return self.view_functions[rule.endpoint](**req.view_args)
  File "C:\Users\domwh\PycharmProjects\Recommender-Systems-Coursework\app\main\routes.py", line 46, in user
    recommendations = user.get_recommendations()
  File "C:\Users\domwh\PycharmProjects\Recommender-Systems-Coursework\app\models.py", line 70, in get_recommendations
    for (user_id, track_id, prediction) in predictions.itertuples():
ValueError: too many values to unpack (expected 3)
2020-03-10 12:57:59,363 INFO: ffgt86 startup [in C:\Users\domwh\PycharmProjects\Recommender-Systems-Coursework\app\__init__.py:56]
2020-03-10 12:58:02,262 ERROR: Exception on /user/20 [GET] [in c:\users\domwh\pycharmprojects\recommender-systems-coursework\venv\lib\site-packages\flask\app.py:1891]
Traceback (most recent call last):
  File "c:\users\domwh\pycharmprojects\recommender-systems-coursework\venv\lib\site-packages\flask\app.py", line 2446, in wsgi_app
    response = self.full_dispatch_request()
  File "c:\users\domwh\pycharmprojects\recommender-systems-coursework\venv\lib\site-packages\flask\app.py", line 1951, in full_dispatch_request
    rv = self.handle_user_exception(e)
  File "c:\users\domwh\pycharmprojects\recommender-systems-coursework\venv\lib\site-packages\flask\app.py", line 1820, in handle_user_exception
    reraise(exc_type, exc_value, tb)
  File "c:\users\domwh\pycharmprojects\recommender-systems-coursework\venv\lib\site-packages\flask\_compat.py", line 39, in reraise
    raise value
  File "c:\users\domwh\pycharmprojects\recommender-systems-coursework\venv\lib\site-packages\flask\app.py", line 1949, in full_dispatch_request
    rv = self.dispatch_request()
  File "c:\users\domwh\pycharmprojects\recommender-systems-coursework\venv\lib\site-packages\flask\app.py", line 1935, in dispatch_request
    return self.view_functions[rule.endpoint](**req.view_args)
  File "C:\Users\domwh\PycharmProjects\Recommender-Systems-Coursework\app\main\routes.py", line 46, in user
    recommendations = user.get_recommendations()
  File "C:\Users\domwh\PycharmProjects\Recommender-Systems-Coursework\app\models.py", line 73, in get_recommendations
    for i, (user_id, track_id, prediction) in predictions.itertuples():
ValueError: too many values to unpack (expected 2)
2020-03-10 12:58:39,144 INFO: ffgt86 startup [in C:\Users\domwh\PycharmProjects\Recommender-Systems-Coursework\app\__init__.py:56]
2020-03-10 12:58:39,708 ERROR: Exception on /user/20 [GET] [in c:\users\domwh\pycharmprojects\recommender-systems-coursework\venv\lib\site-packages\flask\app.py:1891]
Traceback (most recent call last):
  File "c:\users\domwh\pycharmprojects\recommender-systems-coursework\venv\lib\site-packages\flask\app.py", line 2446, in wsgi_app
    response = self.full_dispatch_request()
  File "c:\users\domwh\pycharmprojects\recommender-systems-coursework\venv\lib\site-packages\flask\app.py", line 1951, in full_dispatch_request
    rv = self.handle_user_exception(e)
  File "c:\users\domwh\pycharmprojects\recommender-systems-coursework\venv\lib\site-packages\flask\app.py", line 1820, in handle_user_exception
    reraise(exc_type, exc_value, tb)
  File "c:\users\domwh\pycharmprojects\recommender-systems-coursework\venv\lib\site-packages\flask\_compat.py", line 39, in reraise
    raise value
  File "c:\users\domwh\pycharmprojects\recommender-systems-coursework\venv\lib\site-packages\flask\app.py", line 1949, in full_dispatch_request
    rv = self.dispatch_request()
  File "c:\users\domwh\pycharmprojects\recommender-systems-coursework\venv\lib\site-packages\flask\app.py", line 1935, in dispatch_request
    return self.view_functions[rule.endpoint](**req.view_args)
  File "C:\Users\domwh\PycharmProjects\Recommender-Systems-Coursework\app\main\routes.py", line 46, in user
    recommendations = user.get_recommendations()
  File "C:\Users\domwh\PycharmProjects\Recommender-Systems-Coursework\app\models.py", line 73, in get_recommendations
    for i, x in predictions.itertuples():
ValueError: too many values to unpack (expected 2)
2020-03-10 12:59:53,662 INFO: ffgt86 startup [in C:\Users\domwh\PycharmProjects\Recommender-Systems-Coursework\app\__init__.py:56]
2020-03-10 12:59:57,167 ERROR: Exception on /user/20 [GET] [in c:\users\domwh\pycharmprojects\recommender-systems-coursework\venv\lib\site-packages\flask\app.py:1891]
Traceback (most recent call last):
  File "c:\users\domwh\pycharmprojects\recommender-systems-coursework\venv\lib\site-packages\flask\app.py", line 2446, in wsgi_app
    response = self.full_dispatch_request()
  File "c:\users\domwh\pycharmprojects\recommender-systems-coursework\venv\lib\site-packages\flask\app.py", line 1951, in full_dispatch_request
    rv = self.handle_user_exception(e)
  File "c:\users\domwh\pycharmprojects\recommender-systems-coursework\venv\lib\site-packages\flask\app.py", line 1820, in handle_user_exception
    reraise(exc_type, exc_value, tb)
  File "c:\users\domwh\pycharmprojects\recommender-systems-coursework\venv\lib\site-packages\flask\_compat.py", line 39, in reraise
    raise value
  File "c:\users\domwh\pycharmprojects\recommender-systems-coursework\venv\lib\site-packages\flask\app.py", line 1949, in full_dispatch_request
    rv = self.dispatch_request()
  File "c:\users\domwh\pycharmprojects\recommender-systems-coursework\venv\lib\site-packages\flask\app.py", line 1935, in dispatch_request
    return self.view_functions[rule.endpoint](**req.view_args)
  File "C:\Users\domwh\PycharmProjects\Recommender-Systems-Coursework\app\main\routes.py", line 46, in user
    recommendations = user.get_recommendations()
  File "C:\Users\domwh\PycharmProjects\Recommender-Systems-Coursework\app\models.py", line 71, in get_recommendations
    track = Track.query.get(row["track_id"])
TypeError: tuple indices must be integers or slices, not str
2020-03-10 13:00:28,681 INFO: ffgt86 startup [in C:\Users\domwh\PycharmProjects\Recommender-Systems-Coursework\app\__init__.py:56]
