2020-03-08 10:54:46,858 ERROR: Exception on /user/1 [GET] [in c:\users\domwh\pycharmprojects\recommender-systems-coursework\venv\lib\site-packages\flask\app.py:1891]
Traceback (most recent call last):
  File "c:\users\domwh\pycharmprojects\recommender-systems-coursework\venv\lib\site-packages\flask\app.py", line 2446, in wsgi_app
    response = self.full_dispatch_request()
  File "c:\users\domwh\pycharmprojects\recommender-systems-coursework\venv\lib\site-packages\flask\app.py", line 1951, in full_dispatch_request
    rv = self.handle_user_exception(e)
  File "c:\users\domwh\pycharmprojects\recommender-systems-coursework\venv\lib\site-packages\flask\app.py", line 1820, in handle_user_exception
    reraise(exc_type, exc_value, tb)
  File "c:\users\domwh\pycharmprojects\recommender-systems-coursework\venv\lib\site-packages\flask\_compat.py", line 39, in reraise
    raise value
  File "c:\users\domwh\pycharmprojects\recommender-systems-coursework\venv\lib\site-packages\flask\app.py", line 1949, in full_dispatch_request
    rv = self.dispatch_request()
  File "c:\users\domwh\pycharmprojects\recommender-systems-coursework\venv\lib\site-packages\flask\app.py", line 1935, in dispatch_request
    return self.view_functions[rule.endpoint](**req.view_args)
  File "C:\Users\domwh\PycharmProjects\Recommender-Systems-Coursework\app\main\routes.py", line 49, in user
    recommendations = user.get_recommendations(None)
  File "C:\Users\domwh\PycharmProjects\Recommender-Systems-Coursework\app\models.py", line 57, in get_recommendations
    events = pd.DataFrame([dict(event) for event in self.events.all()])
  File "C:\Users\domwh\PycharmProjects\Recommender-Systems-Coursework\app\models.py", line 57, in <listcomp>
    events = pd.DataFrame([dict(event) for event in self.events.all()])
TypeError: 'Event' object is not iterable
2020-03-08 10:57:08,255 INFO: ffgt86 startup [in C:\Users\domwh\PycharmProjects\Recommender-Systems-Coursework\app\__init__.py:56]
2020-03-08 10:57:17,714 ERROR: Exception on /user/1 [GET] [in c:\users\domwh\pycharmprojects\recommender-systems-coursework\venv\lib\site-packages\flask\app.py:1891]
Traceback (most recent call last):
  File "c:\users\domwh\pycharmprojects\recommender-systems-coursework\venv\lib\site-packages\flask\app.py", line 2446, in wsgi_app
    response = self.full_dispatch_request()
  File "c:\users\domwh\pycharmprojects\recommender-systems-coursework\venv\lib\site-packages\flask\app.py", line 1951, in full_dispatch_request
    rv = self.handle_user_exception(e)
  File "c:\users\domwh\pycharmprojects\recommender-systems-coursework\venv\lib\site-packages\flask\app.py", line 1820, in handle_user_exception
    reraise(exc_type, exc_value, tb)
  File "c:\users\domwh\pycharmprojects\recommender-systems-coursework\venv\lib\site-packages\flask\_compat.py", line 39, in reraise
    raise value
  File "c:\users\domwh\pycharmprojects\recommender-systems-coursework\venv\lib\site-packages\flask\app.py", line 1949, in full_dispatch_request
    rv = self.dispatch_request()
  File "c:\users\domwh\pycharmprojects\recommender-systems-coursework\venv\lib\site-packages\flask\app.py", line 1935, in dispatch_request
    return self.view_functions[rule.endpoint](**req.view_args)
  File "C:\Users\domwh\PycharmProjects\Recommender-Systems-Coursework\app\main\routes.py", line 49, in user
    recommendations = user.get_recommendations(None)
  File "C:\Users\domwh\PycharmProjects\Recommender-Systems-Coursework\app\models.py", line 57, in get_recommendations
    events = pd.read_sql(self.events.all(), self.session.bind)
AttributeError: 'User' object has no attribute 'session'
2020-03-08 10:58:10,871 INFO: ffgt86 startup [in C:\Users\domwh\PycharmProjects\Recommender-Systems-Coursework\app\__init__.py:56]
2020-03-08 10:58:52,214 ERROR: Exception on /user/1 [GET] [in c:\users\domwh\pycharmprojects\recommender-systems-coursework\venv\lib\site-packages\flask\app.py:1891]
Traceback (most recent call last):
  File "c:\users\domwh\pycharmprojects\recommender-systems-coursework\venv\lib\site-packages\flask\app.py", line 2446, in wsgi_app
    response = self.full_dispatch_request()
  File "c:\users\domwh\pycharmprojects\recommender-systems-coursework\venv\lib\site-packages\flask\app.py", line 1951, in full_dispatch_request
    rv = self.handle_user_exception(e)
  File "c:\users\domwh\pycharmprojects\recommender-systems-coursework\venv\lib\site-packages\flask\app.py", line 1820, in handle_user_exception
    reraise(exc_type, exc_value, tb)
  File "c:\users\domwh\pycharmprojects\recommender-systems-coursework\venv\lib\site-packages\flask\_compat.py", line 39, in reraise
    raise value
  File "c:\users\domwh\pycharmprojects\recommender-systems-coursework\venv\lib\site-packages\flask\app.py", line 1949, in full_dispatch_request
    rv = self.dispatch_request()
  File "c:\users\domwh\pycharmprojects\recommender-systems-coursework\venv\lib\site-packages\flask\app.py", line 1935, in dispatch_request
    return self.view_functions[rule.endpoint](**req.view_args)
  File "C:\Users\domwh\PycharmProjects\Recommender-Systems-Coursework\app\main\routes.py", line 49, in user
    recommendations = user.get_recommendations(None)
  File "C:\Users\domwh\PycharmProjects\Recommender-Systems-Coursework\app\models.py", line 61, in get_recommendations
    events = pd.read_sql(self.events.all(), self.session.bind)
AttributeError: 'User' object has no attribute 'session'
2020-03-08 11:03:10,852 INFO: ffgt86 startup [in C:\Users\domwh\PycharmProjects\Recommender-Systems-Coursework\app\__init__.py:56]
